# Analytics 500 Error - Fixed

## Problem

The analytics endpoint was throwing a 500 Internal Server Error:
```
GET /analytics/639cd1d6-4d7e-44e4-aea5-9251c0061900
Status: 500 Internal Server Error
```

Error in frontend:
```javascript
Error fetching user analytics: 
{
  message: "Request failed with status code 500",
  code: "ERR_BAD_RESPONSE",
  status: 500
}
```

## Root Cause

The `user_management_service` in `backend/routes/analytics.py` was being initialized incorrectly:

```python
# BEFORE (BROKEN)
user_management_service = get_user_management_service(None)  # Will be injected
supabase = get_supabase_client()
```

The `get_user_management_service()` function requires a Supabase client to work, but was being passed `None`, causing it to fail when trying to access user data.

## Solution

### 1. Fixed Service Initialization

```python
# AFTER (FIXED)
supabase = get_supabase_client()
user_management_service = get_user_management_service(supabase)  # Pass supabase client
```

Now the user management service receives the Supabase client it needs to function properly.

### 2. Added Comprehensive Logging

Added detailed logging throughout the analytics endpoints to help debug issues:

```python
@router.get("/analytics/{user_id}")
async def get_user_analytics(user_id: str):
    try:
        logger.info(f"📊 Analytics request for user: {user_id}")
        
        # Check if services are available
        if not user_management_service:
            logger.error("❌ User management service not available")
            raise HTTPException(status_code=500, detail="User management service not available")
        
        if not supabase:
            logger.error("❌ Supabase client not available")
            raise HTTPException(status_code=500, detail="Database connection not available")
        
        logger.info(f"🔍 Fetching user data for: {user_id}")
        user_data = await user_management_service.get_user_by_id(user_id)
        
        if not user_data:
            logger.warning(f"⚠️ User not found: {user_id}")
            raise HTTPException(status_code=404, detail="User not found")
        
        logger.info(f"✅ User found: {user_id}, plan: {user_data.get('current_plan')}")
        
        # ... rest of logic ...
        
        logger.info(f"✅ Analytics data successfully generated for user: {user_id}")
        return {"analytics": analytics_data}
        
    except HTTPException as he:
        logger.error(f"❌ HTTP Exception in analytics: {he.status_code} - {he.detail}")
        raise he
    except Exception as e:
        logger.error(f"❌ Analytics error for user {user_id}: {str(e)}")
        logger.exception("Full traceback:")
        raise HTTPException(status_code=500, detail=f"Analytics error: {str(e)}")
```

### 3. Updated All Analytics Endpoints

Applied the same fixes to all endpoints in `analytics.py`:

1. **`POST /badges/check/{user_id}`** - Award badges
2. **`GET /badges/{user_id}`** - Get user badges
3. **`GET /analytics/{user_id}`** - Get analytics data

All now have:
- Proper service initialization checks
- Detailed logging
- Improved error handling
- HTTP exception separation

## Files Modified

### `backend/routes/analytics.py`

**Changes:**
1. Line 17-18: Fixed service initialization order
2. Line 61-75: Added logging to badge check endpoint
3. Line 177-183: Improved badge check error handling
4. Line 189-206: Added logging and validation to badge retrieval
5. Line 212-227: Added comprehensive logging to analytics endpoint
6. Line 373-380: Improved analytics error handling with separate HTTP exception handling

## Testing

### Before Fix
```bash
curl http://localhost:8000/analytics/639cd1d6-4d7e-44e4-aea5-9251c0061900
# Returns: 500 Internal Server Error
```

### After Fix
```bash
curl http://localhost:8000/analytics/639cd1d6-4d7e-44e4-aea5-9251c0061900
# Returns: 
# - 200 OK with analytics data (if user has unlimited plan)
# - 403 Forbidden (if user doesn't have unlimited plan)
# - 404 Not Found (if user doesn't exist)
```

## Log Output (After Fix)

Successful request:
```
📊 Analytics request for user: 639cd1d6-4d7e-44e4-aea5-9251c0061900
🔍 Fetching user data for: 639cd1d6-4d7e-44e4-aea5-9251c0061900
✅ User found: 639cd1d6-4d7e-44e4-aea5-9251c0061900, plan: unlimited
✅ Analytics data successfully generated for user: 639cd1d6-4d7e-44e4-aea5-9251c0061900
```

Failed request (user not found):
```
📊 Analytics request for user: invalid-user-id
🔍 Fetching user data for: invalid-user-id
⚠️ User not found: invalid-user-id
❌ HTTP Exception in analytics: 404 - User not found
```

Failed request (service error):
```
📊 Analytics request for user: test-user
❌ User management service not available
❌ HTTP Exception in analytics: 500 - User management service not available
```

## Benefits

### 1. **Fixed Critical Bug**
- Analytics endpoint now works properly
- User management service properly initialized

### 2. **Better Error Messages**
- Clear distinction between different error types:
  - 404: User not found
  - 403: User doesn't have analytics access
  - 500: Service/database errors
- Detailed error messages for debugging

### 3. **Improved Debugging**
- Comprehensive logging at each step
- Easy to identify where failures occur
- Full stack traces for unexpected errors

### 4. **Better User Experience**
- Users get appropriate error messages
- Frontend can handle different error types appropriately
- Analytics dashboard loads successfully for unlimited users

## Related Components

### Frontend Analytics Dashboard
`frontend/src/components/AnalyticsDashboard/AnalyticsDashboard.js`

Now receives proper responses:
- Success: Shows analytics with AI insights
- 403: Shows locked analytics page
- 404/500: Shows error message

### Frontend Analytics Service
`frontend/src/services/analytics.js`

```javascript
export const getUserAnalytics = async (userId, filters = {}) => {
  try {
    const url = `${API_ENDPOINTS.ANALYTICS}/${userId}`;
    const response = await apiHelpers.get(url, {}, {
      cache: true,
      cacheTime: 120000,
      deduplicate: true
    });
    return response.data;  // Now works correctly!
  } catch (error) {
    console.error('Error fetching user analytics:', error);
    throw error;
  }
};
```

## Prevention

To prevent similar issues in the future:

### 1. Always Initialize Services in Correct Order
```python
# ✅ GOOD
supabase = get_supabase_client()
user_service = get_user_management_service(supabase)

# ❌ BAD
user_service = get_user_management_service(None)
supabase = get_supabase_client()
```

### 2. Add Validation Checks
```python
if not user_management_service:
    raise HTTPException(status_code=500, detail="Service not available")

if not supabase:
    raise HTTPException(status_code=500, detail="Database not available")
```

### 3. Add Comprehensive Logging
```python
logger.info(f"📊 Request received")
logger.info(f"🔍 Processing...")
logger.info(f"✅ Success")
logger.error(f"❌ Error: {error}")
```

### 4. Separate Error Handling
```python
try:
    # ... logic ...
except HTTPException as he:
    # Re-raise HTTP exceptions
    raise he
except Exception as e:
    # Log and wrap unexpected errors
    logger.exception("Full traceback:")
    raise HTTPException(status_code=500, detail=str(e))
```

## Deployment Notes

After deploying this fix:

1. **Restart Backend Server**:
   ```bash
   cd backend
   pkill -f uvicorn
   source venv/bin/activate
   uvicorn server:app --host 0.0.0.0 --port 8000 --reload
   ```

2. **Test Analytics Endpoint**:
   ```bash
   # Replace with actual user ID
   curl http://localhost:8000/analytics/{user_id}
   ```

3. **Check Logs**:
   ```bash
   tail -f backend/backend.log
   ```

4. **Test Frontend**:
   - Navigate to Analytics page
   - Should load without errors
   - AI Insights button should work

## Status

✅ **FIXED** - Analytics endpoint now works correctly with proper service initialization and comprehensive error handling.

## Related Issues

This fix also resolves:
- Badge endpoints returning 500 errors
- User management service initialization issues
- Missing error context in logs

## Monitoring

Monitor these metrics after deployment:
- Analytics endpoint success rate (should be > 95%)
- 500 error count (should drop to near 0)
- Average response time
- User complaints about analytics not loading

## Rollback Plan

If issues occur, rollback by reverting:
```bash
git checkout HEAD~1 backend/routes/analytics.py
```

Then restart the backend server.

